 Tue, 03 Mar 2020 22:01:02  INFO logger.py <module> [ line:20 ] hehehehe
 Tue, 03 Mar 2020 22:01:02  ERROR logger.py <module> [ line:21 ] heheheheheheh
Traceback (most recent call last):
  File "D:\Program Files (x86)\python\lib\site-packages\_pytest\config\__init__.py", line 456, in _importconftest
    return self._conftestpath2mod[key]
KeyError: WindowsPath('D:/python/mystudy/AppFramework/TestCases/conftest.py')
 Tue, 03 Mar 2020 22:01:56  INFO logger.py <module> [ line:20 ] hehehehe
 Tue, 03 Mar 2020 22:01:56  ERROR logger.py <module> [ line:21 ] heheheheheheh
Traceback (most recent call last):
  File "D:\Program Files (x86)\python\lib\site-packages\_pytest\config\__init__.py", line 456, in _importconftest
    return self._conftestpath2mod[key]
KeyError: WindowsPath('D:/python/mystudy/AppFramework/TestCases/conftest.py')
 Tue, 03 Mar 2020 22:01:56  INFO conftest.py init_session [ line:60 ] xxxxxxx
 Tue, 03 Mar 2020 22:01:57  INFO remote_connection.py __init__ [ line:116 ] Could not connect to port 4723 on host 127.0.0.1
 Tue, 03 Mar 2020 22:01:57  INFO remote_connection.py __init__ [ line:135 ] Could not get IP address for host: 127.0.0.1
 Tue, 03 Mar 2020 22:01:58  WARNING connectionpool.py urlopen [ line:744 ] Retrying (Retry(total=2, connect=None, read=None, redirect=None, status=None)) after connection broken by 'NewConnectionError('<urllib3.connection.HTTPConnection object at 0x000001E1C6EFAB80>: Failed to establish a new connection: [WinError 10061] 由于目标计算机积极拒绝，无法连接。')': /wd/hub/session
 Tue, 03 Mar 2020 22:01:59  WARNING connectionpool.py urlopen [ line:744 ] Retrying (Retry(total=1, connect=None, read=None, redirect=None, status=None)) after connection broken by 'NewConnectionError('<urllib3.connection.HTTPConnection object at 0x000001E1C6EFAE50>: Failed to establish a new connection: [WinError 10061] 由于目标计算机积极拒绝，无法连接。')': /wd/hub/session
 Tue, 03 Mar 2020 22:02:00  WARNING connectionpool.py urlopen [ line:744 ] Retrying (Retry(total=0, connect=None, read=None, redirect=None, status=None)) after connection broken by 'NewConnectionError('<urllib3.connection.HTTPConnection object at 0x000001E1C6EFAFD0>: Failed to establish a new connection: [WinError 10061] 由于目标计算机积极拒绝，无法连接。')': /wd/hub/session
 Tue, 03 Mar 2020 22:02:03  INFO remote_connection.py __init__ [ line:116 ] Could not connect to port 4723 on host 127.0.0.1
 Tue, 03 Mar 2020 22:02:03  INFO remote_connection.py __init__ [ line:135 ] Could not get IP address for host: 127.0.0.1
 Tue, 03 Mar 2020 22:02:04  WARNING connectionpool.py urlopen [ line:744 ] Retrying (Retry(total=2, connect=None, read=None, redirect=None, status=None)) after connection broken by 'NewConnectionError('<urllib3.connection.HTTPConnection object at 0x000001E1C784D7C0>: Failed to establish a new connection: [WinError 10061] 由于目标计算机积极拒绝，无法连接。')': /wd/hub/session
 Tue, 03 Mar 2020 22:02:05  WARNING connectionpool.py urlopen [ line:744 ] Retrying (Retry(total=1, connect=None, read=None, redirect=None, status=None)) after connection broken by 'NewConnectionError('<urllib3.connection.HTTPConnection object at 0x000001E1C784DA30>: Failed to establish a new connection: [WinError 10061] 由于目标计算机积极拒绝，无法连接。')': /wd/hub/session
 Tue, 03 Mar 2020 22:02:06  WARNING connectionpool.py urlopen [ line:744 ] Retrying (Retry(total=0, connect=None, read=None, redirect=None, status=None)) after connection broken by 'NewConnectionError('<urllib3.connection.HTTPConnection object at 0x000001E1C784D9D0>: Failed to establish a new connection: [WinError 10061] 由于目标计算机积极拒绝，无法连接。')': /wd/hub/session
